<?xml version="1.0"?>
<robot name="diff_bot">

  <link name="base_footprint"/>

  <joint name="base_joint" type="fixed">
    <origin xyz="0 0 0.02"/>
    <parent link="base_footprint"/>
    <child link="base_link"/>
  </joint>

  <link name="base_link"/>

  <joint name="left_wheel_joint" type="continuous">
    <axis xyz="0 0 1.0"/>
    <parent link="base_link"/>
    <child link="left_wheel"/>
    <origin rpy="-1.57 0 0" xyz="0 0.11 0"/>
  </joint>
  
  <link name="left_wheel"/>

  <joint name="right_wheel_joint" type="continuous">
    <axis xyz="0.0 0.0 1"/>
    <parent link="base_link"/>
    <child link="right_wheel"/>
    <origin rpy="-1.57 0 0" xyz="0 -0.11 0"/>
  </joint>
  
  <link name="right_wheel"/>

  <joint name="lidar_joint" type="fixed">
    <origin xyz="0 0 0.17"/>
    <parent link="base_link"/>
    <child link="lidar_link"/>
  </joint>

  <link name="lidar_link"/>
</robot>